Workbook

Sheet Настройки
A1: Сводная интерполяция процентных кривых | B1: Сводная интерполяция процентных кривых | C1: Сводная интерполяция процентных кривых | D1: Сводная интерполяция процентных кривых
A3: Параметр | B3: Значение
A4: Дата отчёта | B4: 46203
A5: Дневная база | B5: 365
A6: Метод | B6: Линейная интерполяция
A8: Обозначение | B8: Единица | C8: Тип | D8: Примечание
A9: КБД | B9: % | C9: Исходная кривая | D9: КБД Московской биржи на 30.06.2026
A10: Сценарная кривая | B10: % | C10: Сценарий | D10: КБД со сценарным сдвигом из исходной таблицы
A11: ЦБ_shock_up/down | B11: б.п. | C11: Шок | D11: Значения из таблицы ЦБ
A12: RUB вверх/вниз | B12: п.п. | C12: Шок | D12: Рублёвые процентные сдвиги
A14: Правила расчёта
A15: Срок | B15: (дата платежа − дата отчёта) / 365
A16: За границами | B16: Используется ближайшее крайнее значение кривой

Sheet Исходные кривые
A1: Исходные узлы кривых | B1: Исходные узлы кривых | C1: Исходные узлы кривых | D1: Исходные узлы кривых | E1: Исходные узлы кривых | F1: Исходные узлы кривых | G1: Исходные узлы кривых | H1: Исходные узлы кривых | I1: Исходные узлы кривых | J1: Исходные узлы кривых | K1: Исходные узлы кривых | L1: Исходные узлы кривых | M1: Исходные узлы кривых | N1: Исходные узлы кривых | O1: Исходные узлы кривых
A3: КБД Московской биржи
A4: Срок, лет | B4: 0.25 | C4: 0.5 | D4: 0.75 | E4: 1 | F4: 2 | G4: 3 | H4: 5 | I4: 7 | J4: 10 | K4: 15 | L4: 20
A5: КБД, % | B5: 13.59 | C5: 13.44 | D5: 13.39 | E5: 13.41 | F5: 13.87 | G5: 14.47 | H5: 15.42 | I5: 15.98 | J5: 16.38 | K5: 16.65 | L5: 16.78
A7: Сценарная кривая
A8: Срок, лет | B8: 0 | C8: 0.25 | D8: 0.5 | E8: 0.75 | F8: 1 | G8: 2 | H8: 3 | I8: 5 | J8: 7 | K8: 10 | L8: 15 | M8: 20 | N8: 30
A9: Ставка, % | B9: 15.59 | C9: 15.59 | D9: 15.44 | E9: 15.39 | F9: 15.41 | G9: 15.87 | H9: 16.47 | I9: 17.42 | J9: 17.98 | K9: 18.38 | L9: 18.65 | M9: 18.78 | N9: 18.93
A11: Шоки ЦБ
A12: Срок, лет | B12: 0.25 | C12: 0.5 | D12: 1 | E12: 2 | F12: 3 | G12: 5 | H12: 7 | I12: 10 | J12: 20 | K12: 30
A13: ЦБ_shock_up, б.п. | B13: 62 | C13: 59 | D13: 58 | E13: 55 | F13: 54 | G13: 48 | H13: 42 | I13: 34 | J13: 20 | K13: 14
A14: ЦБ_shock_down, б.п. | B14: -38 | C14: -35 | D14: -31 | E14: -29 | F14: -28 | G14: -27 | H14: -26 | I14: -24 | J14: -18 | K14: -15
A16: Сдвиги RUB
A17: Срок, лет | B17: 0 | C17: 0.08 | D17: 0.25 | E17: 0.5 | F17: 0.75 | G17: 1 | H17: 2 | I17: 3 | J17: 4 | K17: 5 | L17: 100
A18: Сдвиг вверх, п.п. | B18: 5.75 | C18: 5.75 | D18: 5.75 | E18: 4.8 | F18: 5.2 | G18: 6 | H18: 7.25 | I18: 6.4 | J18: 6.15 | K18: 5.4 | L18: 5.4
A19: Сдвиг вниз, п.п. | B19: -2.55 | C19: -2.55 | D19: -2.55 | E19: -3.35 | F19: -4.3 | G19: -5 | H19: -4.7 | I19: -3.65 | J19: -2.85 | K19: -1.9 | L19: -1.9

Sheet Результаты
A1: Все интерполяции на заданные даты | B1: Все интерполяции на заданные даты | C1: Все интерполяции на заданные даты | D1: Все интерполяции на заданные даты | E1: Все интерполяции на заданные даты | F1: Все интерполяции на заданные даты | G1: Все интерполяции на заданные даты | H1: Все интерполяции на заданные даты | I1: Все интерполяции на заданные даты
A3: Дата | B3: Дней | C3: Срок ACT/365, лет | D3: КБД, % | E3: Сценарная кривая, % | F3: ЦБ_shock_up, б.п. | G3: ЦБ_shock_down, б.п. | H3: RUB вверх, п.п. | I3: RUB вниз, п.п.
A4: 46203 | B4: =A4-Настройки!$B$4 -> 0 | C4: =B4/Настройки!$B$5 -> 0 | D4: =IF(C4<=MIN('Исходные кривые'!$B$4:$L$4),INDEX('Исходные кривые'!$B$5:$L$5,1,1),IF(C4>=MAX('Исходные кривые'!$B$4:$L$4),INDEX('Исходные кривые'!$B$5:$L$5,1,COLUMNS('Исходные кривые'!$B$5:$L$5)),INDEX('Исходные кривые'!$B$5:$L$5,1,MATCH(C4,'Исходные кривые'!$B$4:$L$4,1))+(C4-INDEX('Исходные кривые'!$B$4:$L$4,1,MATCH(C4,'Исходные кривые'!$B$4:$L$4,1)))*(INDEX('Исходные кривые'!$B$5:$L$5,1,MATCH(C4,'Исходные кривые'!$B$4:$L$4,1)+1)-INDEX('Исходные кривые'!$B$5:$L$5,1,MATCH(C4,'Исходные кривые'!$B$4:$L$4,1)))/(INDEX('Исходные кривые'!$B$4:$L$4,1,MATCH(C4,'Исходные кривые'!$B$4:$L$4,1)+1)-INDEX('Исходные кривые'!$B$4:$L$4,1,MATCH(C4,'Исходные кривые'!$B$4:$L$4,1))))) -> 13.59 | E4: =IF(C4<=MIN('Исходные кривые'!$B$8:$N$8),INDEX('Исходные кривые'!$B$9:$N$9,1,1),IF(C4>=MAX('Исходные кривые'!$B$8:$N$8),INDEX('Исходные кривые'!$B$9:$N$9,1,COLUMNS('Исходные кривые'!$B$9:$N$9)),INDEX('Исходные кривые'!$B$9:$N$9,1,MATCH(C4,'Исходные кривые'!$B$8:$N$8,1))+(C4-INDEX('Исходные кривые'!$B$8:$N$8,1,MATCH(C4,'Исходные кривые'!$B$8:$N$8,1)))*(INDEX('Исходные кривые'!$B$9:$N$9,1,MATCH(C4,'Исходные кривые'!$B$8:$N$8,1)+1)-INDEX('Исходные кривые'!$B$9:$N$9,1,MATCH(C4,'Исходные кривые'!$B$8:$N$8,1)))/(INDEX('Исходные кривые'!$B$8:$N$8,1,MATCH(C4,'Исходные кривые'!$B$8:$N$8,1)+1)-INDEX('Исходные кривые'!$B$8:$N$8,1,MATCH(C4,'Исходные кривые'!$B$8:$N$8,1))))) -> 15.59 | F4: =IF(C4<=MIN('Исходные кривые'!$B$12:$K$12),INDEX('Исходные кривые'!$B$13:$K$13,1,1),IF(C4>=MAX('Исходные кривые'!$B$12:$K$12),INDEX('Исходные кривые'!$B$13:$K$13,1,COLUMNS('Исходные кривые'!$B$13:$K$13)),INDEX('Исходные кривые'!$B$13:$K$13,1,MATCH(C4,'Исходные кривые'!$B$12:$K$12,1))+(C4-INDEX('Исходные кривые'!$B$12:$K$12,1,MATCH(C4,'Исходные кривые'!$B$12:$K$12,1)))*(INDEX('Исходные кривые'!$B$13:$K$13,1,MATCH(C4,'Исходные кривые'!$B$12:$K$12,1)+1)-INDEX('Исходные кривые'!$B$13:$K$13,1,MATCH(C4,'Исходные кривые'!$B$12:$K$12,1)))/(INDEX('Исходные кривые'!$B$12:$K$12,1,MATCH(C4,'Исходные кривые'!$B$12:$K$12,1)+1)-INDEX('Исходные кривые'!$B$12:$K$12,1,MATCH(C4,'Исходные кривые'!$B$12:$K$12,1))))) -> 62 | G4: =IF(C4<=MIN('Исходные кривые'!$B$12:$K$12),INDEX('Исходные кривые'!$B$14:$K$14,1,1),IF(C4>=MAX('Исходные кривые'!$B$12:$K$12),INDEX('Исходные кривые'!$B$14:$K$14,1,COLUMNS('Исходные кривые'!$B$14:$K$14)),INDEX('Исходные кривые'!$B$14:$K$14,1,MATCH(C4,'Исходные кривые'!$B$12:$K$12,1))+(C4-INDEX('Исходные кривые'!$B$12:$K$12,1,MATCH(C4,'Исходные кривые'!$B$12:$K$12,1)))*(INDEX('Исходные кривые'!$B$14:$K$14,1,MATCH(C4,'Исходные кривые'!$B$12:$K$12,1)+1)-INDEX('Исходные кривые'!$B$14:$K$14,1,MATCH(C4,'Исходные кривые'!$B$12:$K$12,1)))/(INDEX('Исходные кривые'!$B$12:$K$12,1,MATCH(C4,'Исходные кривые'!$B$12:$K$12,1)+1)-INDEX('Исходные кривые'!$B$12:$K$12,1,MATCH(C4,'Исходные кривые'!$B$12:$K$12,1))))) -> -38 | H4: =IF(C4<=MIN('Исходные кривые'!$B$17:$L$17),INDEX('Исходные кривые'!$B$18:$L$18,1,1),IF(C4>=MAX('Исходные кривые'!$B$17:$L$17),INDEX('Исходные кривые'!$B$18:$L$18,1,COLUMNS('Исходные кривые'!$B$18:$L$18)),INDEX('Исходные кривые'!$B$18:$L$18,1,MATCH(C4,'Исходные кривые'!$B$17:$L$17,1))+(C4-INDEX('Исходные кривые'!$B$17:$L$17,1,MATCH(C4,'Исходные кривые'!$B$17:$L$17,1)))*(INDEX('Исходные кривые'!$B$18:$L$18,1,MATCH(C4,'Исходные кривые'!$B$17:$L$17,1)+1)-INDEX('Исходные кривые'!$B$18:$L$18,1,MATCH(C4,'Исходные кривые'!$B$17:$L$17,1)))/(INDEX('Исходные кривые'!$B$17:$L$17,1,MATCH(C4,'Исходные кривые'!$B$17:$L$17,1)+1)-INDEX('Исходные кривые'!$B$17:$L$17,1,MATCH(C4,'Исходные кривые'!$B$17:$L$17,1))))) -> 5.75 | I4: =IF(C4<=MIN('Исходные кривые'!$B$17:$L$17),INDEX('Исходные кривые'!$B$19:$L$19,1,1),IF(C4>=MAX('Исходные кривые'!$B$17:$L$17),INDEX('Исходные кривые'!$B$19:$L$19,1,COLUMNS('Исходные кривые'!$B$19:$L$19)),INDEX('Исходные кривые'!$B$19:$L$19,1,MATCH(C4,'Исходные кривые'!$B$17:$L$17,1))+(C4-INDEX('Исходные кривые'!$B$17:$L$17,1,MATCH(C4,'Исходные кривые'!$B$17:$L$17,1)))*(INDEX('Исходные кривые'!$B$19:$L$19,1,MATCH(C4,'Исходные кривые'!$B$17:$L$17,1)+1)-INDEX('Исходные кривые'!$B$19:$L$19,1,MATCH(C4,'Исходные кривые'!$B$17:$L$17,1)))/(INDEX('Исходные кривые'!$B$17:$L$17,1,MATCH(C4,'Исходные кривые'!$B$17:$L$17,1)+1)-INDEX('Исходные кривые'!$B$17:$L$17,1,MATCH(C4,'Исходные кривые'!$B$17:$L$17,1))))) -> -2.55
A5: 46568 | B5: =A5-Настройки!$B$4 -> 365 | C5: =B5/Настройки!$B$5 -> 1 | D5: =IF(C5<=MIN('Исходные кривые'!$B$4:$L$4),INDEX('Исходные кривые'!$B$5:$L$5,1,1),IF(C5>=MAX('Исходные кривые'!$B$4:$L$4),INDEX('Исходные кривые'!$B$5:$L$5,1,COLUMNS('Исходные кривые'!$B$5:$L$5)),INDEX('Исходные кривые'!$B$5:$L$5,1,MATCH(C5,'Исходные кривые'!$B$4:$L$4,1))+(C5-INDEX('Исходные кривые'!$B$4:$L$4,1,MATCH(C5,'Исходные кривые'!$B$4:$L$4,1)))*(INDEX('Исходные кривые'!$B$5:$L$5,1,MATCH(C5,'Исходные кривые'!$B$4:$L$4,1)+1)-INDEX('Исходные кривые'!$B$5:$L$5,1,MATCH(C5,'Исходные кривые'!$B$4:$L$4,1)))/(INDEX('Исходные кривые'!$B$4:$L$4,1,MATCH(C5,'Исходные кривые'!$B$4:$L$4,1)+1)-INDEX('Исходные кривые'!$B$4:$L$4,1,MATCH(C5,'Исходные кривые'!$B$4:$L$4,1))))) -> 13.41 | E5: =IF(C5<=MIN('Исходные кривые'!$B$8:$N$8),INDEX('Исходные кривые'!$B$9:$N$9,1,1),IF(C5>=MAX('Исходные кривые'!$B$8:$N$8),INDEX('Исходные кривые'!$B$9:$N$9,1,COLUMNS('Исходные кривые'!$B$9:$N$9)),INDEX('Исходные кривые'!$B$9:$N$9,1,MATCH(C5,'Исходные кривые'!$B$8:$N$8,1))+(C5-INDEX('Исходные кривые'!$B$8:$N$8,1,MATCH(C5,'Исходные кривые'!$B$8:$N$8,1)))*(INDEX('Исходные кривые'!$B$9:$N$9,1,MATCH(C5,'Исходные кривые'!$B$8:$N$8,1)+1)-INDEX('Исходные кривые'!$B$9:$N$9,1,MATCH(C5,'Исходные кривые'!$B$8:$N$8,1)))/(INDEX('Исходные кривые'!$B$8:$N$8,1,MATCH(C5,'Исходные кривые'!$B$8:$N$8,1)+1)-INDEX('Исходные кривые'!$B$8:$N$8,1,MATCH(C5,'Исходные кривые'!$B$8:$N$8,1))))) -> 15.41 | F5: =IF(C5<=MIN('Исходные кривые'!$B$12:$K$12),INDEX('Исходные кривые'!$B$13:$K$13,1,1),IF(C5>=MAX('Исходные кривые'!$B$12:$K$12),INDEX('Исходные кривые'!$B$13:$K$13,1,COLUMNS('Исходные кривые'!$B$13:$K$13)),INDEX('Исходные кривые'!$B$13:$K$13,1,MATCH(C5,'Исходные кривые'!$B$12:$K$12,1))+(C5-INDEX('Исходные кривые'!$B$12:$K$12,1,MATCH(C5,'Исходные кривые'!$B$12:$K$12,1)))*(INDEX('Исходные кривые'!$B$13:$K$13,1,MATCH(C5,'Исходные кривые'!$B$12:$K$12,1)+1)-INDEX('Исходные кривые'!$B$13:$K$13,1,MATCH(C5,'Исходные кривые'!$B$12:$K$12,1)))/(INDEX('Исходные кривые'!$B$12:$K$12,1,MATCH(C5,'Исходные кривые'!$B$12:$K$12,1)+1)-INDEX('Исходные кривые'!$B$12:$K$12,1,MATCH(C5,'Исходные кривые'!$B$12:$K$12,1))))) -> 58 | G5: =IF(C5<=MIN('Исходные кривые'!$B$12:$K$12),INDEX('Исходные кривые'!$B$14:$K$14,1,1),IF(C5>=MAX('Исходные кривые'!$B$12:$K$12),INDEX('Исходные кривые'!$B$14:$K$14,1,COLUMNS('Исходные кривые'!$B$14:$K$14)),INDEX('Исходные кривые'!$B$14:$K$14,1,MATCH(C5,'Исходные кривые'!$B$12:$K$12,1))+(C5-INDEX('Исходные кривые'!$B$12:$K$12,1,MATCH(C5,'Исходные кривые'!$B$12:$K$12,1)))*(INDEX('Исходные кривые'!$B$14:$K$14,1,MATCH(C5,'Исходные кривые'!$B$12:$K$12,1)+1)-INDEX('Исходные кривые'!$B$14:$K$14,1,MATCH(C5,'Исходные кривые'!$B$12:$K$12,1)))/(INDEX('Исходные кривые'!$B$12:$K$12,1,MATCH(C5,'Исходные кривые'!$B$12:$K$12,1)+1)-INDEX('Исходные кривые'!$B$12:$K$12,1,MATCH(C5,'Исходные кривые'!$B$12:$K$12,1))))) -> -31 | H5: =IF(C5<=MIN('Исходные кривые'!$B$17:$L$17),INDEX('Исходные кривые'!$B$18:$L$18,1,1),IF(C5>=MAX('Исходные кривые'!$B$17:$L$17),INDEX('Исходные кривые'!$B$18:$L$18,1,COLUMNS('Исходные кривые'!$B$18:$L$18)),INDEX('Исходные кривые'!$B$18:$L$18,1,MATCH(C5,'Исходные кривые'!$B$17:$L$17,1))+(C5-INDEX('Исходные кривые'!$B$17:$L$17,1,MATCH(C5,'Исходные кривые'!$B$17:$L$17,1)))*(INDEX('Исходные кривые'!$B$18:$L$18,1,MATCH(C5,'Исходные кривые'!$B$17:$L$17,1)+1)-INDEX('Исходные кривые'!$B$18:$L$18,1,MATCH(C5,'Исходные кривые'!$B$17:$L$17,1)))/(INDEX('Исходные кривые'!$B$17:$L$17,1,MATCH(C5,'Исходные кривые'!$B$17:$L$17,1)+1)-INDEX('Исходные кривые'!$B$17:$L$17,1,MATCH(C5,'Исходные кривые'!$B$17:$L$17,1))))) -> 6 | I5: =IF(C5<=MIN('Исходные кривые'!$B$17:$L$17),INDEX('Исходные кривые'!$B$19:$L$19,1,1),IF(C5>=MAX('Исходные кривые'!$B$17:$L$17),INDEX('Исходные кривые'!$B$19:$L$19,1,COLUMNS('Исходные кривые'!$B$19:$L$19)),INDEX('Исходные кривые'!$B$19:$L$19,1,MATCH(C5,'Исходные кривые'!$B$17:$L$17,1))+(C5-INDEX('Исходные кривые'!$B$17:$L$17,1,MATCH(C5,'Исходные кривые'!$B$17:$L$17,1)))*(INDEX('Исходные кривые'!$B$19:$L$19,1,MATCH(C5,'Исходные кривые'!$B$17:$L$17,1)+1)-INDEX('Исходные кривые'!$B$19:$L$19,1,MATCH(C5,'Исходные кривые'!$B$17:$L$17,1)))/(INDEX('Исходные кривые'!$B$17:$L$17,1,MATCH(C5,'Исходные кривые'!$B$17:$L$17,1)+1)-INDEX('Исходные кривые'!$B$17:$L$17,1,MATCH(C5,'Исходные кривые'!$B$17:$L$17,1))))) -> -5
A6: 46934 | B6: =A6-Настройки!$B$4 -> 731 | C6: =B6/Настройки!$B$5 -> 2.0027397 | D6: =IF(C6<=MIN('Исходные кривые'!$B$4:$L$4),INDEX('Исходные кривые'!$B$5:$L$5,1,1),IF(C6>=MAX('Исходные кривые'!$B$4:$L$4),INDEX('Исходные кривые'!$B$5:$L$5,1,COLUMNS('Исходные кривые'!$B$5:$L$5)),INDEX('Исходные кривые'!$B$5:$L$5,1,MATCH(C6,'Исходные кривые'!$B$4:$L$4,1))+(C6-INDEX('Исходные кривые'!$B$4:$L$4,1,MATCH(C6,'Исходные кривые'!$B$4:$L$4,1)))*(INDEX('Исходные кривые'!$B$5:$L$5,1,MATCH(C6,'Исходные кривые'!$B$4:$L$4,1)+1)-INDEX('Исходные кривые'!$B$5:$L$5,1,MATCH(C6,'Исходные кривые'!$B$4:$L$4,1)))/(INDEX('Исходные кривые'!$B$4:$L$4,1,MATCH(C6,'Исходные кривые'!$B$4:$L$4,1)+1)-INDEX('Исходные кривые'!$B$4:$L$4,1,MATCH(C6,'Исходные кривые'!$B$4:$L$4,1))))) -> 13.871644 | E6: =IF(C6<=MIN('Исходные кривые'!$B$8:$N$8),INDEX('Исходные кривые'!$B$9:$N$9,1,1),IF(C6>=MAX('Исходные кривые'!$B$8:$N$8),INDEX('Исходные кривые'!$B$9:$N$9,1,COLUMNS('Исходные кривые'!$B$9:$N$9)),INDEX('Исходные кривые'!$B$9:$N$9,1,MATCH(C6,'Исходные кривые'!$B$8:$N$8,1))+(C6-INDEX('Исходные кривые'!$B$8:$N$8,1,MATCH(C6,'Исходные кривые'!$B$8:$N$8,1)))*(INDEX('Исходные кривые'!$B$9:$N$9,1,MATCH(C6,'Исходные кривые'!$B$8:$N$8,1)+1)-INDEX('Исходные кривые'!$B$9:$N$9,1,MATCH(C6,'Исходные кривые'!$B$8:$N$8,1)))/(INDEX('Исходные кривые'!$B$8:$N$8,1,MATCH(C6,'Исходные кривые'!$B$8:$N$8,1)+1)-INDEX('Исходные кривые'!$B$8:$N$8,1,MATCH(C6,'Исходные кривые'!$B$8:$N$8,1))))) -> 15.871644 | F6: =IF(C6<=MIN('Исходные кривые'!$B$12:$K$12),INDEX('Исходные кривые'!$B$13:$K$13,1,1),IF(C6>=MAX('Исходные кривые'!$B$12:$K$12),INDEX('Исходные кривые'!$B$13:$K$13,1,COLUMNS('Исходные кривые'!$B$13:$K$13)),INDEX('Исходные кривые'!$B$13:$K$13,1,MATCH(C6,'Исходные кривые'!$B$12:$K$12,1))+(C6-INDEX('Исходные кривые'!$B$12:$K$12,1,MATCH(C6,'Исходные кривые'!$B$12:$K$12,1)))*(INDEX('Исходные кривые'!$B$13:$K$13,1,MATCH(C6,'Исходные кривые'!$B$12:$K$12,1)+1)-INDEX('Исходные кривые'!$B$13:$K$13,1,MATCH(C6,'Исходные кривые'!$B$12:$K$12,1)))/(INDEX('Исходные кривые'!$B$12:$K$12,1,MATCH(C6,'Исходные кривые'!$B$12:$K$12,1)+1)-INDEX('Исходные кривые'!$B$12:$K$12,1,MATCH(C6,'Исходные кривые'!$B$12:$K$12,1))))) -> 54.99726 | G6: =IF(C6<=MIN('Исходные кривые'!$B$12:$K$12),INDEX('Исходные кривые'!$B$14:$K$14,1,1),IF(C6>=MAX('Исходные кривые'!$B$12:$K$12),INDEX('Исходные кривые'!$B$14:$K$14,1,COLUMNS('Исходные кривые'!$B$14:$K$14)),INDEX('Исходные кривые'!$B$14:$K$14,1,MATCH(C6,'Исходные кривые'!$B$12:$K$12,1))+(C6-INDEX('Исходные кривые'!$B$12:$K$12,1,MATCH(C6,'Исходные кривые'!$B$12:$K$12,1)))*(INDEX('Исходные кривые'!$B$14:$K$14,1,MATCH(C6,'Исходные кривые'!$B$12:$K$12,1)+1)-INDEX('Исходные кривые'!$B$14:$K$14,1,MATCH(C6,'Исходные кривые'!$B$12:$K$12,1)))/(INDEX('Исходные кривые'!$B$12:$K$12,1,MATCH(C6,'Исходные кривые'!$B$12:$K$12,1)+1)-INDEX('Исходные кривые'!$B$12:$K$12,1,MATCH(C6,'Исходные кривые'!$B$12:$K$12,1))))) -> -28.99726 | H6: =IF(C6<=MIN('Исходные кривые'!$B$17:$L$17),INDEX('Исходные кривые'!$B$18:$L$18,1,1),IF(C6>=MAX('Исходные кривые'!$B$17:$L$17),INDEX('Исходные кривые'!$B$18:$L$18,1,COLUMNS('Исходные кривые'!$B$18:$L$18)),INDEX('Исходные кривые'!$B$18:$L$18,1,MATCH(C6,'Исходные кривые'!$B$17:$L$17,1))+(C6-INDEX('Исходные кривые'!$B$17:$L$17,1,MATCH(C6,'Исходные кривые'!$B$17:$L$17,1)))*(INDEX('Исходные кривые'!$B$18:$L$18,1,MATCH(C6,'Исходные кривые'!$B$17:$L$17,1)+1)-INDEX('Исходные кривые'!$B$18:$L$18,1,MATCH(C6,'Исходные кривые'!$B$17:$L$17,1)))/(INDEX('Исходные кривые'!$B$17:$L$17,1,MATCH(C6,'Исходные кривые'!$B$17:$L$17,1)+1)-INDEX('Исходные кривые'!$B$17:$L$17,1,MATCH(C6,'Исходные кривые'!$B$17:$L$17,1))))) -> 7.2476712 | I6: =IF(C6<=MIN('Исходные кривые'!$B$17:$L$17),INDEX('Исходные кривые'!$B$19:$L$19,1,1),IF(C6>=MAX('Исходные кривые'!$B$17:$L$17),INDEX('Исходные кривые'!$B$19:$L$19,1,COLUMNS('Исходные кривые'!$B$19:$L$19)),INDEX('Исходные кривые'!$B$19:$L$19,1,MATCH(C6,'Исходные кривые'!$B$17:$L$17,1))+(C6-INDEX('Исходные кривые'!$B$17:$L$17,1,MATCH(C6,'Исходные кривые'!$B$17:$L$17,1)))*(INDEX('Исходные кривые'!$B$19:$L$19,1,MATCH(C6,'Исходные кривые'!$B$17:$L$17,1)+1)-INDEX('Исходные кривые'!$B$19:$L$19,1,MATCH(C6,'Исходные кривые'!$B$17:$L$17,1)))/(INDEX('Исходные кривые'!$B$17:$L$17,1,MATCH(C6,'Исходные кривые'!$B$17:$L$17,1)+1)-INDEX('Исходные кривые'!$B$17:$L$17,1,MATCH(C6,'Исходные кривые'!$B$17:$L$17,1))))) -> -4.6971233
A7: 47299 | B7: =A7-Настройки!$B$4 -> 1096 | C7: =B7/Настройки!$B$5 -> 3.0027397 | D7: =IF(C7<=MIN('Исходные кривые'!$B$4:$L$4),INDEX('Исходные кривые'!$B$5:$L$5,1,1),IF(C7>=MAX('Исходные кривые'!$B$4:$L$4),INDEX('Исходные кривые'!$B$5:$L$5,1,COLUMNS('Исходные кривые'!$B$5:$L$5)),INDEX('Исходные кривые'!$B$5:$L$5,1,MATCH(C7,'Исходные кривые'!$B$4:$L$4,1))+(C7-INDEX('Исходные кривые'!$B$4:$L$4,1,MATCH(C7,'Исходные кривые'!$B$4:$L$4,1)))*(INDEX('Исходные кривые'!$B$5:$L$5,1,MATCH(C7,'Исходные кривые'!$B$4:$L$4,1)+1)-INDEX('Исходные кривые'!$B$5:$L$5,1,MATCH(C7,'Исходные кривые'!$B$4:$L$4,1)))/(INDEX('Исходные кривые'!$B$4:$L$4,1,MATCH(C7,'Исходные кривые'!$B$4:$L$4,1)+1)-INDEX('Исходные кривые'!$B$4:$L$4,1,MATCH(C7,'Исходные кривые'!$B$4:$L$4,1))))) -> 14.471301 | E7: =IF(C7<=MIN('Исходные кривые'!$B$8:$N$8),INDEX('Исходные кривые'!$B$9:$N$9,1,1),IF(C7>=MAX('Исходные кривые'!$B$8:$N$8),INDEX('Исходные кривые'!$B$9:$N$9,1,COLUMNS('Исходные кривые'!$B$9:$N$9)),INDEX('Исходные кривые'!$B$9:$N$9,1,MATCH(C7,'Исходные кривые'!$B$8:$N$8,1))+(C7-INDEX('Исходные кривые'!$B$8:$N$8,1,MATCH(C7,'Исходные кривые'!$B$8:$N$8,1)))*(INDEX('Исходные кривые'!$B$9:$N$9,1,MATCH(C7,'Исходные кривые'!$B$8:$N$8,1)+1)-INDEX('Исходные кривые'!$B$9:$N$9,1,MATCH(C7,'Исходные кривые'!$B$8:$N$8,1)))/(INDEX('Исходные кривые'!$B$8:$N$8,1,MATCH(C7,'Исходные кривые'!$B$8:$N$8,1)+1)-INDEX('Исходные кривые'!$B$8:$N$8,1,MATCH(C7,'Исходные кривые'!$B$8:$N$8,1))))) -> 16.471301 | F7: =IF(C7<=MIN('Исходные кривые'!$B$12:$K$12),INDEX('Исходные кривые'!$B$13:$K$13,1,1),IF(C7>=MAX('Исходные кривые'!$B$12:$K$12),INDEX('Исходные кривые'!$B$13:$K$13,1,COLUMNS('Исходные кривые'!$B$13:$K$13)),INDEX('Исходные кривые'!$B$13:$K$13,1,MATCH(C7,'Исходные кривые'!$B$12:$K$12,1))+(C7-INDEX('Исходные кривые'!$B$12:$K$12,1,MATCH(C7,'Исходные кривые'!$B$12:$K$12,1)))*(INDEX('Исходные кривые'!$B$13:$K$13,1,MATCH(C7,'Исходные кривые'!$B$12:$K$12,1)+1)-INDEX('Исходные кривые'!$B$13:$K$13,1,MATCH(C7,'Исходные кривые'!$B$12:$K$12,1)))/(INDEX('Исходные кривые'!$B$12:$K$12,1,MATCH(C7,'Исходные кривые'!$B$12:$K$12,1)+1)-INDEX('Исходные кривые'!$B$12:$K$12,1,MATCH(C7,'Исходные кривые'!$B$12:$K$12,1))))) -> 53.991781 | G7: =IF(C7<=MIN('Исходные кривые'!$B$12:$K$12),INDEX('Исходные кривые'!$B$14:$K$14,1,1),IF(C7>=MAX('Исходные кривые'!$B$12:$K$12),INDEX('Исходные кривые'!$B$14:$K$14,1,COLUMNS('Исходные кривые'!$B$14:$K$14)),INDEX('Исходные кривые'!$B$14:$K$14,1,MATCH(C7,'Исходные кривые'!$B$12:$K$12,1))+(C7-INDEX('Исходные кривые'!$B$12:$K$12,1,MATCH(C7,'Исходные кривые'!$B$12:$K$12,1)))*(INDEX('Исходные кривые'!$B$14:$K$14,1,MATCH(C7,'Исходные кривые'!$B$12:$K$12,1)+1)-INDEX('Исходные кривые'!$B$14:$K$14,1,MATCH(C7,'Исходные кривые'!$B$12:$K$12,1)))/(INDEX('Исходные кривые'!$B$12:$K$12,1,MATCH(C7,'Исходные кривые'!$B$12:$K$12,1)+1)-INDEX('Исходные кривые'!$B$12:$K$12,1,MATCH(C7,'Исходные кривые'!$B$12:$K$12,1))))) -> -27.99863 | H7: =IF(C7<=MIN('Исходные кривые'!$B$17:$L$17),INDEX('Исходные кривые'!$B$18:$L$18,1,1),IF(C7>=MAX('Исходные кривые'!$B$17:$L$17),INDEX('Исходные кривые'!$B$18:$L$18,1,COLUMNS('Исходные кривые'!$B$18:$L$18)),INDEX('Исходные кривые'!$B$18:$L$18,1,MATCH(C7,'Исходные кривые'!$B$17:$L$17,1))+(C7-INDEX('Исходные кривые'!$B$17:$L$17,1,MATCH(C7,'Исходные кривые'!$B$17:$L$17,1)))*(INDEX('Исходные кривые'!$B$18:$L$18,1,MATCH(C7,'Исходные кривые'!$B$17:$L$17,1)+1)-INDEX('Исходные кривые'!$B$18:$L$18,1,MATCH(C7,'Исходные кривые'!$B$17:$L$17,1)))/(INDEX('Исходные кривые'!$B$17:$L$17,1,MATCH(C7,'Исходные кривые'!$B$17:$L$17,1)+1)-INDEX('Исходные кривые'!$B$17:$L$17,1,MATCH(C7,'Исходные кривые'!$B$17:$L$17,1))))) -> 6.3993151 | I7: =IF(C7<=MIN('Исходные кривые'!$B$17:$L$17),INDEX('Исходные кривые'!$B$19:$L$19,1,1),IF(C7>=MAX('Исходные кривые'!$B$17:$L$17),INDEX('Исходные кривые'!$B$19:$L$19,1,COLUMNS('Исходные кривые'!$B$19:$L$19)),INDEX('Исходные кривые'!$B$19:$L$19,1,MATCH(C7,'Исходные кривые'!$B$17:$L$17,1))+(C7-INDEX('Исходные кривые'!$B$17:$L$17,1,MATCH(C7,'Исходные кривые'!$B$17:$L$17,1)))*(INDEX('Исходные кривые'!$B$19:$L$19,1,MATCH(C7,'Исходные кривые'!$B$17:$L$17,1)+1)-INDEX('Исходные кривые'!$B$19:$L$19,1,MATCH(C7,'Исходные кривые'!$B$17:$L$17,1)))/(INDEX('Исходные кривые'!$B$17:$L$17,1,MATCH(C7,'Исходные кривые'!$B$17:$L$17,1)+1)-INDEX('Исходные кривые'!$B$17:$L$17,1,MATCH(C7,'Исходные кривые'!$B$17:$L$17,1))))) -> -3.6478082
A8: 47664 | B8: =A8-Настройки!$B$4 -> 1461 | C8: =B8/Настройки!$B$5 -> 4.0027397 | D8: =IF(C8<=MIN('Исходные кривые'!$B$4:$L$4),INDEX('Исходные кривые'!$B$5:$L$5,1,1),IF(C8>=MAX('Исходные кривые'!$B$4:$L$4),INDEX('Исходные кривые'!$B$5:$L$5,1,COLUMNS('Исходные кривые'!$B$5:$L$5)),INDEX('Исходные кривые'!$B$5:$L$5,1,MATCH(C8,'Исходные кривые'!$B$4:$L$4,1))+(C8-INDEX('Исходные кривые'!$B$4:$L$4,1,MATCH(C8,'Исходные кривые'!$B$4:$L$4,1)))*(INDEX('Исходные кривые'!$B$5:$L$5,1,MATCH(C8,'Исходные кривые'!$B$4:$L$4,1)+1)-INDEX('Исходные кривые'!$B$5:$L$5,1,MATCH(C8,'Исходные кривые'!$B$4:$L$4,1)))/(INDEX('Исходные кривые'!$B$4:$L$4,1,MATCH(C8,'Исходные кривые'!$B$4:$L$4,1)+1)-INDEX('Исходные кривые'!$B$4:$L$4,1,MATCH(C8,'Исходные кривые'!$B$4:$L$4,1))))) -> 14.946301 | E8: =IF(C8<=MIN('Исходные кривые'!$B$8:$N$8),INDEX('Исходные кривые'!$B$9:$N$9,1,1),IF(C8>=MAX('Исходные кривые'!$B$8:$N$8),INDEX('Исходные кривые'!$B$9:$N$9,1,COLUMNS('Исходные кривые'!$B$9:$N$9)),INDEX('Исходные кривые'!$B$9:$N$9,1,MATCH(C8,'Исходные кривые'!$B$8:$N$8,1))+(C8-INDEX('Исходные кривые'!$B$8:$N$8,1,MATCH(C8,'Исходные кривые'!$B$8:$N$8,1)))*(INDEX('Исходные кривые'!$B$9:$N$9,1,MATCH(C8,'Исходные кривые'!$B$8:$N$8,1)+1)-INDEX('Исходные кривые'!$B$9:$N$9,1,MATCH(C8,'Исходные кривые'!$B$8:$N$8,1)))/(INDEX('Исходные кривые'!$B$8:$N$8,1,MATCH(C8,'Исходные кривые'!$B$8:$N$8,1)+1)-INDEX('Исходные кривые'!$B$8:$N$8,1,MATCH(C8,'Исходные кривые'!$B$8:$N$8,1))))) -> 16.946301 | F8: =IF(C8<=MIN('Исходные кривые'!$B$12:$K$12),INDEX('Исходные кривые'!$B$13:$K$13,1,1),IF(C8>=MAX('Исходные кривые'!$B$12:$K$12),INDEX('Исходные кривые'!$B$13:$K$13,1,COLUMNS('Исходные кривые'!$B$13:$K$13)),INDEX('Исходные кривые'!$B$13:$K$13,1,MATCH(C8,'Исходные кривые'!$B$12:$K$12,1))+(C8-INDEX('Исходные кривые'!$B$12:$K$12,1,MATCH(C8,'Исходные кривые'!$B$12:$K$12,1)))*(INDEX('Исходные кривые'!$B$13:$K$13,1,MATCH(C8,'Исходные кривые'!$B$12:$K$12,1)+1)-INDEX('Исходные кривые'!$B$13:$K$13,1,MATCH(C8,'Исходные кривые'!$B$12:$K$12,1)))/(INDEX('Исходные кривые'!$B$12:$K$12,1,MATCH(C8,'Исходные кривые'!$B$12:$K$12,1)+1)-INDEX('Исходные кривые'!$B$12:$K$12,1,MATCH(C8,'Исходные кривые'!$B$12:$K$12,1))))) -> 50.991781 | G8: =IF(C8<=MIN('Исходные кривые'!$B$12:$K$12),INDEX('Исходные кривые'!$B$14:$K$14,1,1),IF(C8>=MAX('Исходные кривые'!$B$12:$K$12),INDEX('Исходные кривые'!$B$14:$K$14,1,COLUMNS('Исходные кривые'!$B$14:$K$14)),INDEX('Исходные кривые'!$B$14:$K$14,1,MATCH(C8,'Исходные кривые'!$B$12:$K$12,1))+(C8-INDEX('Исходные кривые'!$B$12:$K$12,1,MATCH(C8,'Исходные кривые'!$B$12:$K$12,1)))*(INDEX('Исходные кривые'!$B$14:$K$14,1,MATCH(C8,'Исходные кривые'!$B$12:$K$12,1)+1)-INDEX('Исходные кривые'!$B$14:$K$14,1,MATCH(C8,'Исходные кривые'!$B$12:$K$12,1)))/(INDEX('Исходные кривые'!$B$12:$K$12,1,MATCH(C8,'Исходные кривые'!$B$12:$K$12,1)+1)-INDEX('Исходные кривые'!$B$12:$K$12,1,MATCH(C8,'Исходные кривые'!$B$12:$K$12,1))))) -> -27.49863 | H8: =IF(C8<=MIN('Исходные кривые'!$B$17:$L$17),INDEX('Исходные кривые'!$B$18:$L$18,1,1),IF(C8>=MAX('Исходные кривые'!$B$17:$L$17),INDEX('Исходные кривые'!$B$18:$L$18,1,COLUMNS('Исходные кривые'!$B$18:$L$18)),INDEX('Исходные кривые'!$B$18:$L$18,1,MATCH(C8,'Исходные кривые'!$B$17:$L$17,1))+(C8-INDEX('Исходные кривые'!$B$17:$L$17,1,MATCH(C8,'Исходные кривые'!$B$17:$L$17,1)))*(INDEX('Исходные кривые'!$B$18:$L$18,1,MATCH(C8,'Исходные кривые'!$B$17:$L$17,1)+1)-INDEX('Исходные кривые'!$B$18:$L$18,1,MATCH(C8,'Исходные кривые'!$B$17:$L$17,1)))/(INDEX('Исходные кривые'!$B$17:$L$17,1,MATCH(C8,'Исходные кривые'!$B$17:$L$17,1)+1)-INDEX('Исходные кривые'!$B$17:$L$17,1,MATCH(C8,'Исходные кривые'!$B$17:$L$17,1))))) -> 6.1479452 | I8: =IF(C8<=MIN('Исходные кривые'!$B$17:$L$17),INDEX('Исходные кривые'!$B$19:$L$19,1,1),IF(C8>=MAX('Исходные кривые'!$B$17:$L$17),INDEX('Исходные кривые'!$B$19:$L$19,1,COLUMNS('Исходные кривые'!$B$19:$L$19)),INDEX('Исходные кривые'!$B$19:$L$19,1,MATCH(C8,'Исходные кривые'!$B$17:$L$17,1))+(C8-INDEX('Исходные кривые'!$B$17:$L$17,1,MATCH(C8,'Исходные кривые'!$B$17:$L$17,1)))*(INDEX('Исходные кривые'!$B$19:$L$19,1,MATCH(C8,'Исходные кривые'!$B$17:$L$17,1)+1)-INDEX('Исходные кривые'!$B$19:$L$19,1,MATCH(C8,'Исходные кривые'!$B$17:$L$17,1)))/(INDEX('Исходные кривые'!$B$17:$L$17,1,MATCH(C8,'Исходные кривые'!$B$17:$L$17,1)+1)-INDEX('Исходные кривые'!$B$17:$L$17,1,MATCH(C8,'Исходные кривые'!$B$17:$L$17,1))))) -> -2.8473973
A9: 48029 | B9: =A9-Настройки!$B$4 -> 1826 | C9: =B9/Настройки!$B$5 -> 5.0027397 | D9: =IF(C9<=MIN('Исходные кривые'!$B$4:$L$4),INDEX('Исходные кривые'!$B$5:$L$5,1,1),IF(C9>=MAX('Исходные кривые'!$B$4:$L$4),INDEX('Исходные кривые'!$B$5:$L$5,1,COLUMNS('Исходные кривые'!$B$5:$L$5)),INDEX('Исходные кривые'!$B$5:$L$5,1,MATCH(C9,'Исходные кривые'!$B$4:$L$4,1))+(C9-INDEX('Исходные кривые'!$B$4:$L$4,1,MATCH(C9,'Исходные кривые'!$B$4:$L$4,1)))*(INDEX('Исходные кривые'!$B$5:$L$5,1,MATCH(C9,'Исходные кривые'!$B$4:$L$4,1)+1)-INDEX('Исходные кривые'!$B$5:$L$5,1,MATCH(C9,'Исходные кривые'!$B$4:$L$4,1)))/(INDEX('Исходные кривые'!$B$4:$L$4,1,MATCH(C9,'Исходные кривые'!$B$4:$L$4,1)+1)-INDEX('Исходные кривые'!$B$4:$L$4,1,MATCH(C9,'Исходные кривые'!$B$4:$L$4,1))))) -> 15.420767 | E9: =IF(C9<=MIN('Исходные кривые'!$B$8:$N$8),INDEX('Исходные кривые'!$B$9:$N$9,1,1),IF(C9>=MAX('Исходные кривые'!$B$8:$N$8),INDEX('Исходные кривые'!$B$9:$N$9,1,COLUMNS('Исходные кривые'!$B$9:$N$9)),INDEX('Исходные кривые'!$B$9:$N$9,1,MATCH(C9,'Исходные кривые'!$B$8:$N$8,1))+(C9-INDEX('Исходные кривые'!$B$8:$N$8,1,MATCH(C9,'Исходные кривые'!$B$8:$N$8,1)))*(INDEX('Исходные кривые'!$B$9:$N$9,1,MATCH(C9,'Исходные кривые'!$B$8:$N$8,1)+1)-INDEX('Исходные кривые'!$B$9:$N$9,1,MATCH(C9,'Исходные кривые'!$B$8:$N$8,1)))/(INDEX('Исходные кривые'!$B$8:$N$8,1,MATCH(C9,'Исходные кривые'!$B$8:$N$8,1)+1)-INDEX('Исходные кривые'!$B$8:$N$8,1,MATCH(C9,'Исходные кривые'!$B$8:$N$8,1))))) -> 17.420767 | F9: =IF(C9<=MIN('Исходные кривые'!$B$12:$K$12),INDEX('Исходные кривые'!$B$13:$K$13,1,1),IF(C9>=MAX('Исходные кривые'!$B$12:$K$12),INDEX('Исходные кривые'!$B$13:$K$13,1,COLUMNS('Исходные кривые'!$B$13:$K$13)),INDEX('Исходные кривые'!$B$13:$K$13,1,MATCH(C9,'Исходные кривые'!$B$12:$K$12,1))+(C9-INDEX('Исходные кривые'!$B$12:$K$12,1,MATCH(C9,'Исходные кривые'!$B$12:$K$12,1)))*(INDEX('Исходные кривые'!$B$13:$K$13,1,MATCH(C9,'Исходные кривые'!$B$12:$K$12,1)+1)-INDEX('Исходные кривые'!$B$13:$K$13,1,MATCH(C9,'Исходные кривые'!$B$12:$K$12,1)))/(INDEX('Исходные кривые'!$B$12:$K$12,1,MATCH(C9,'Исходные кривые'!$B$12:$K$12,1)+1)-INDEX('Исходные кривые'!$B$12:$K$12,1,MATCH(C9,'Исходные кривые'!$B$12:$K$12,1))))) -> 47.991781 | G9: =IF(C9<=MIN('Исходные кривые'!$B$12:$K$12),INDEX('Исходные кривые'!$B$14:$K$14,1,1),IF(C9>=MAX('Исходные кривые'!$B$12:$K$12),INDEX('Исходные кривые'!$B$14:$K$14,1,COLUMNS('Исходные кривые'!$B$14:$K$14)),INDEX('Исходные кривые'!$B$14:$K$14,1,MATCH(C9,'Исходные кривые'!$B$12:$K$12,1))+(C9-INDEX('Исходные кривые'!$B$12:$K$12,1,MATCH(C9,'Исходные кривые'!$B$12:$K$12,1)))*(INDEX('Исходные кривые'!$B$14:$K$14,1,MATCH(C9,'Исходные кривые'!$B$12:$K$12,1)+1)-INDEX('Исходные кривые'!$B$14:$K$14,1,MATCH(C9,'Исходные кривые'!$B$12:$K$12,1)))/(INDEX('Исходные кривые'!$B$12:$K$12,1,MATCH(C9,'Исходные кривые'!$B$12:$K$12,1)+1)-INDEX('Исходные кривые'!$B$12:$K$12,1,MATCH(C9,'Исходные кривые'!$B$12:$K$12,1))))) -> -26.99863 | H9: =IF(C9<=MIN('Исходные кривые'!$B$17:$L$17),INDEX('Исходные кривые'!$B$18:$L$18,1,1),IF(C9>=MAX('Исходные кривые'!$B$17:$L$17),INDEX('Исходные кривые'!$B$18:$L$18,1,COLUMNS('Исходные кривые'!$B$18:$L$18)),INDEX('Исходные кривые'!$B$18:$L$18,1,MATCH(C9,'Исходные кривые'!$B$17:$L$17,1))+(C9-INDEX('Исходные кривые'!$B$17:$L$17,1,MATCH(C9,'Исходные кривые'!$B$17:$L$17,1)))*(INDEX('Исходные кривые'!$B$18:$L$18,1,MATCH(C9,'Исходные кривые'!$B$17:$L$17,1)+1)-INDEX('Исходные кривые'!$B$18:$L$18,1,MATCH(C9,'Исходные кривые'!$B$17:$L$17,1)))/(INDEX('Исходные кривые'!$B$17:$L$17,1,MATCH(C9,'Исходные кривые'!$B$17:$L$17,1)+1)-INDEX('Исходные кривые'!$B$17:$L$17,1,MATCH(C9,'Исходные кривые'!$B$17:$L$17,1))))) -> 5.4 | I9: =IF(C9<=MIN('Исходные кривые'!$B$17:$L$17),INDEX('Исходные кривые'!$B$19:$L$19,1,1),IF(C9>=MAX('Исходные кривые'!$B$17:$L$17),INDEX('Исходные кривые'!$B$19:$L$19,1,COLUMNS('Исходные кривые'!$B$19:$L$19)),INDEX('Исходные кривые'!$B$19:$L$19,1,MATCH(C9,'Исходные кривые'!$B$17:$L$17,1))+(C9-INDEX('Исходные кривые'!$B$17:$L$17,1,MATCH(C9,'Исходные кривые'!$B$17:$L$17,1)))*(INDEX('Исходные кривые'!$B$19:$L$19,1,MATCH(C9,'Исходные кривые'!$B$17:$L$17,1)+1)-INDEX('Исходные кривые'!$B$19:$L$19,1,MATCH(C9,'Исходные кривые'!$B$17:$L$17,1)))/(INDEX('Исходные кривые'!$B$17:$L$17,1,MATCH(C9,'Исходные кривые'!$B$17:$L$17,1)+1)-INDEX('Исходные кривые'!$B$17:$L$17,1,MATCH(C9,'Исходные кривые'!$B$17:$L$17,1))))) -> -1.9
A10: 46414 | B10: =A10-Настройки!$B$4 -> 211 | C10: =B10/Настройки!$B$5 -> 0.57808219 | D10: =IF(C10<=MIN('Исходные кривые'!$B$4:$L$4),INDEX('Исходные кривые'!$B$5:$L$5,1,1),IF(C10>=MAX('Исходные кривые'!$B$4:$L$4),INDEX('Исходные кривые'!$B$5:$L$5,1,COLUMNS('Исходные кривые'!$B$5:$L$5)),INDEX('Исходные кривые'!$B$5:$L$5,1,MATCH(C10,'Исходные кривые'!$B$4:$L$4,1))+(C10-INDEX('Исходные кривые'!$B$4:$L$4,1,MATCH(C10,'Исходные кривые'!$B$4:$L$4,1)))*(INDEX('Исходные кривые'!$B$5:$L$5,1,MATCH(C10,'Исходные кривые'!$B$4:$L$4,1)+1)-INDEX('Исходные кривые'!$B$5:$L$5,1,MATCH(C10,'Исходные кривые'!$B$4:$L$4,1)))/(INDEX('Исходные кривые'!$B$4:$L$4,1,MATCH(C10,'Исходные кривые'!$B$4:$L$4,1)+1)-INDEX('Исходные кривые'!$B$4:$L$4,1,MATCH(C10,'Исходные кривые'!$B$4:$L$4,1))))) -> 13.424384 | E10: =IF(C10<=MIN('Исходные кривые'!$B$8:$N$8),INDEX('Исходные кривые'!$B$9:$N$9,1,1),IF(C10>=MAX('Исходные кривые'!$B$8:$N$8),INDEX('Исходные кривые'!$B$9:$N$9,1,COLUMNS('Исходные кривые'!$B$9:$N$9)),INDEX('Исходные кривые'!$B$9:$N$9,1,MATCH(C10,'Исходные кривые'!$B$8:$N$8,1))+(C10-INDEX('Исходные кривые'!$B$8:$N$8,1,MATCH(C10,'Исходные кривые'!$B$8:$N$8,1)))*(INDEX('Исходные кривые'!$B$9:$N$9,1,MATCH(C10,'Исходные кривые'!$B$8:$N$8,1)+1)-INDEX('Исходные кривые'!$B$9:$N$9,1,MATCH(C10,'Исходные кривые'!$B$8:$N$8,1)))/(INDEX('Исходные кривые'!$B$8:$N$8,1,MATCH(C10,'Исходные кривые'!$B$8:$N$8,1)+1)-INDEX('Исходные кривые'!$B$8:$N$8,1,MATCH(C10,'Исходные кривые'!$B$8:$N$8,1))))) -> 15.424384 | F10: =IF(C10<=MIN('Исходные кривые'!$B$12:$K$12),INDEX('Исходные кривые'!$B$13:$K$13,1,1),IF(C10>=MAX('Исходные кривые'!$B$12:$K$12),INDEX('Исходные кривые'!$B$13:$K$13,1,COLUMNS('Исходные кривые'!$B$13:$K$13)),INDEX('Исходные кривые'!$B$13:$K$13,1,MATCH(C10,'Исходные кривые'!$B$12:$K$12,1))+(C10-INDEX('Исходные кривые'!$B$12:$K$12,1,MATCH(C10,'Исходные кривые'!$B$12:$K$12,1)))*(INDEX('Исходные кривые'!$B$13:$K$13,1,MATCH(C10,'Исходные кривые'!$B$12:$K$12,1)+1)-INDEX('Исходные кривые'!$B$13:$K$13,1,MATCH(C10,'Исходные кривые'!$B$12:$K$12,1)))/(INDEX('Исходные кривые'!$B$12:$K$12,1,MATCH(C10,'Исходные кривые'!$B$12:$K$12,1)+1)-INDEX('Исходные кривые'!$B$12:$K$12,1,MATCH(C10,'Исходные кривые'!$B$12:$K$12,1))))) -> 58.843836 | G10: =IF(C10<=MIN('Исходные кривые'!$B$12:$K$12),INDEX('Исходные кривые'!$B$14:$K$14,1,1),IF(C10>=MAX('Исходные кривые'!$B$12:$K$12),INDEX('Исходные кривые'!$B$14:$K$14,1,COLUMNS('Исходные кривые'!$B$14:$K$14)),INDEX('Исходные кривые'!$B$14:$K$14,1,MATCH(C10,'Исходные кривые'!$B$12:$K$12,1))+(C10-INDEX('Исходные кривые'!$B$12:$K$12,1,MATCH(C10,'Исходные кривые'!$B$12:$K$12,1)))*(INDEX('Исходные кривые'!$B$14:$K$14,1,MATCH(C10,'Исходные кривые'!$B$12:$K$12,1)+1)-INDEX('Исходные кривые'!$B$14:$K$14,1,MATCH(C10,'Исходные кривые'!$B$12:$K$12,1)))/(INDEX('Исходные кривые'!$B$12:$K$12,1,MATCH(C10,'Исходные кривые'!$B$12:$K$12,1)+1)-INDEX('Исходные кривые'!$B$12:$K$12,1,MATCH(C10,'Исходные кривые'!$B$12:$K$12,1))))) -> -34.375342 | H10: =IF(C10<=MIN('Исходные кривые'!$B$17:$L$17),INDEX('Исходные кривые'!$B$18:$L$18,1,1),IF(C10>=MAX('Исходные кривые'!$B$17:$L$17),INDEX('Исходные кривые'!$B$18:$L$18,1,COLUMNS('Исходные кривые'!$B$18:$L$18)),INDEX('Исходные кривые'!$B$18:$L$18,1,MATCH(C10,'Исходные кривые'!$B$17:$L$17,1))+(C10-INDEX('Исходные кривые'!$B$17:$L$17,1,MATCH(C10,'Исходные кривые'!$B$17:$L$17,1)))*(INDEX('Исходные кривые'!$B$18:$L$18,1,MATCH(C10,'Исходные кривые'!$B$17:$L$17,1)+1)-INDEX('Исходные кривые'!$B$18:$L$18,1,MATCH(C10,'Исходные кривые'!$B$17:$L$17,1)))/(INDEX('Исходные кривые'!$B$17:$L$17,1,MATCH(C10,'Исходные кривые'!$B$17:$L$17,1)+1)-INDEX('Исходные кривые'!$B$17:$L$17,1,MATCH(C10,'Исходные кривые'!$B$17:$L$17,1))))) -> 4.9249315 | I10: =IF(C10<=MIN('Исходные кривые'!$B$17:$L$17),INDEX('Исходные кривые'!$B$19:$L$19,1,1),IF(C10>=MAX('Исходные кривые'!$B$17:$L$17),INDEX('Исходные кривые'!$B$19:$L$19,1,COLUMNS('Исходные кривые'!$B$19:$L$19)),INDEX('Исходные кривые'!$B$19:$L$19,1,MATCH(C10,'Исходные кривые'!$B$17:$L$17,1))+(C10-INDEX('Исходные кривые'!$B$17:$L$17,1,MATCH(C10,'Исходные кривые'!$B$17:$L$17,1)))*(INDEX('Исходные кривые'!$B$19:$L$19,1,MATCH(C10,'Исходные кривые'!$B$17:$L$17,1)+1)-INDEX('Исходные кривые'!$B$19:$L$19,1,MATCH(C10,'Исходные кривые'!$B$17:$L$17,1)))/(INDEX('Исходные кривые'!$B$17:$L$17,1,MATCH(C10,'Исходные кривые'!$B$17:$L$17,1)+1)-INDEX('Исходные кривые'!$B$17:$L$17,1,MATCH(C10,'Исходные кривые'!$B$17:$L$17,1))))) -> -3.6467123
A11: 46596 | B11: =A11-Настройки!$B$4 -> 393 | C11: =B11/Настройки!$B$5 -> 1.0767123 | D11: =IF(C11<=MIN('Исходные кривые'!$B$4:$L$4),INDEX('Исходные кривые'!$B$5:$L$5,1,1),IF(C11>=MAX('Исходные кривые'!$B$4:$L$4),INDEX('Исходные кривые'!$B$5:$L$5,1,COLUMNS('Исходные кривые'!$B$5:$L$5)),INDEX('Исходные кривые'!$B$5:$L$5,1,MATCH(C11,'Исходные кривые'!$B$4:$L$4,1))+(C11-INDEX('Исходные кривые'!$B$4:$L$4,1,MATCH(C11,'Исходные кривые'!$B$4:$L$4,1)))*(INDEX('Исходные кривые'!$B$5:$L$5,1,MATCH(C11,'Исходные кривые'!$B$4:$L$4,1)+1)-INDEX('Исходные кривые'!$B$5:$L$5,1,MATCH(C11,'Исходные кривые'!$B$4:$L$4,1)))/(INDEX('Исходные кривые'!$B$4:$L$4,1,MATCH(C11,'Исходные кривые'!$B$4:$L$4,1)+1)-INDEX('Исходные кривые'!$B$4:$L$4,1,MATCH(C11,'Исходные кривые'!$B$4:$L$4,1))))) -> 13.445288 | E11: =IF(C11<=MIN('Исходные кривые'!$B$8:$N$8),INDEX('Исходные кривые'!$B$9:$N$9,1,1),IF(C11>=MAX('Исходные кривые'!$B$8:$N$8),INDEX('Исходные кривые'!$B$9:$N$9,1,COLUMNS('Исходные кривые'!$B$9:$N$9)),INDEX('Исходные кривые'!$B$9:$N$9,1,MATCH(C11,'Исходные кривые'!$B$8:$N$8,1))+(C11-INDEX('Исходные кривые'!$B$8:$N$8,1,MATCH(C11,'Исходные кривые'!$B$8:$N$8,1)))*(INDEX('Исходные кривые'!$B$9:$N$9,1,MATCH(C11,'Исходные кривые'!$B$8:$N$8,1)+1)-INDEX('Исходные кривые'!$B$9:$N$9,1,MATCH(C11,'Исходные кривые'!$B$8:$N$8,1)))/(INDEX('Исходные кривые'!$B$8:$N$8,1,MATCH(C11,'Исходные кривые'!$B$8:$N$8,1)+1)-INDEX('Исходные кривые'!$B$8:$N$8,1,MATCH(C11,'Исходные кривые'!$B$8:$N$8,1))))) -> 15.445288 | F11: =IF(C11<=MIN('Исходные кривые'!$B$12:$K$12),INDEX('Исходные кривые'!$B$13:$K$13,1,1),IF(C11>=MAX('Исходные кривые'!$B$12:$K$12),INDEX('Исходные кривые'!$B$13:$K$13,1,COLUMNS('Исходные кривые'!$B$13:$K$13)),INDEX('Исходные кривые'!$B$13:$K$13,1,MATCH(C11,'Исходные кривые'!$B$12:$K$12,1))+(C11-INDEX('Исходные кривые'!$B$12:$K$12,1,MATCH(C11,'Исходные кривые'!$B$12:$K$12,1)))*(INDEX('Исходные кривые'!$B$13:$K$13,1,MATCH(C11,'Исходные кривые'!$B$12:$K$12,1)+1)-INDEX('Исходные кривые'!$B$13:$K$13,1,MATCH(C11,'Исходные кривые'!$B$12:$K$12,1)))/(INDEX('Исходные кривые'!$B$12:$K$12,1,MATCH(C11,'Исходные кривые'!$B$12:$K$12,1)+1)-INDEX('Исходные кривые'!$B$12:$K$12,1,MATCH(C11,'Исходные кривые'!$B$12:$K$12,1))))) -> 57.769863 | G11: =IF(C11<=MIN('Исходные кривые'!$B$12:$K$12),INDEX('Исходные кривые'!$B$14:$K$14,1,1),IF(C11>=MAX('Исходные кривые'!$B$12:$K$12),INDEX('Исходные кривые'!$B$14:$K$14,1,COLUMNS('Исходные кривые'!$B$14:$K$14)),INDEX('Исходные кривые'!$B$14:$K$14,1,MATCH(C11,'Исходные кривые'!$B$12:$K$12,1))+(C11-INDEX('Исходные кривые'!$B$12:$K$12,1,MATCH(C11,'Исходные кривые'!$B$12:$K$12,1)))*(INDEX('Исходные кривые'!$B$14:$K$14,1,MATCH(C11,'Исходные кривые'!$B$12:$K$12,1)+1)-INDEX('Исходные кривые'!$B$14:$K$14,1,MATCH(C11,'Исходные кривые'!$B$12:$K$12,1)))/(INDEX('Исходные кривые'!$B$12:$K$12,1,MATCH(C11,'Исходные кривые'!$B$12:$K$12,1)+1)-INDEX('Исходные кривые'!$B$12:$K$12,1,MATCH(C11,'Исходные кривые'!$B$12:$K$12,1))))) -> -30.846575 | H11: =IF(C11<=MIN('Исходные кривые'!$B$17:$L$17),INDEX('Исходные кривые'!$B$18:$L$18,1,1),IF(C11>=MAX('Исходные кривые'!$B$17:$L$17),INDEX('Исходные кривые'!$B$18:$L$18,1,COLUMNS('Исходные кривые'!$B$18:$L$18)),INDEX('Исходные кривые'!$B$18:$L$18,1,MATCH(C11,'Исходные кривые'!$B$17:$L$17,1))+(C11-INDEX('Исходные кривые'!$B$17:$L$17,1,MATCH(C11,'Исходные кривые'!$B$17:$L$17,1)))*(INDEX('Исходные кривые'!$B$18:$L$18,1,MATCH(C11,'Исходные кривые'!$B$17:$L$17,1)+1)-INDEX('Исходные кривые'!$B$18:$L$18,1,MATCH(C11,'Исходные кривые'!$B$17:$L$17,1)))/(INDEX('Исходные кривые'!$B$17:$L$17,1,MATCH(C11,'Исходные кривые'!$B$17:$L$17,1)+1)-INDEX('Исходные кривые'!$B$17:$L$17,1,MATCH(C11,'Исходные кривые'!$B$17:$L$17,1))))) -> 6.0958904 | I11: =IF(C11<=MIN('Исходные кривые'!$B$17:$L$17),INDEX('Исходные кривые'!$B$19:$L$19,1,1),IF(C11>=MAX('Исходные кривые'!$B$17:$L$17),INDEX('Исходные кривые'!$B$19:$L$19,1,COLUMNS('Исходные кривые'!$B$19:$L$19)),INDEX('Исходные кривые'!$B$19:$L$19,1,MATCH(C11,'Исходные кривые'!$B$17:$L$17,1))+(C11-INDEX('Исходные кривые'!$B$17:$L$17,1,MATCH(C11,'Исходные кривые'!$B$17:$L$17,1)))*(INDEX('Исходные кривые'!$B$19:$L$19,1,MATCH(C11,'Исходные кривые'!$B$17:$L$17,1)+1)-INDEX('Исходные кривые'!$B$19:$L$19,1,MATCH(C11,'Исходные кривые'!$B$17:$L$17,1)))/(INDEX('Исходные кривые'!$B$17:$L$17,1,MATCH(C11,'Исходные кривые'!$B$17:$L$17,1)+1)-INDEX('Исходные кривые'!$B$17:$L$17,1,MATCH(C11,'Исходные кривые'!$B$17:$L$17,1))))) -> -4.9769863
A12: 46778 | B12: =A12-Настройки!$B$4 -> 575 | C12: =B12/Настройки!$B$5 -> 1.5753425 | D12: =IF(C12<=MIN('Исходные кривые'!$B$4:$L$4),INDEX('Исходные кривые'!$B$5:$L$5,1,1),IF(C12>=MAX('Исходные кривые'!$B$4:$L$4),INDEX('Исходные кривые'!$B$5:$L$5,1,COLUMNS('Исходные кривые'!$B$5:$L$5)),INDEX('Исходные кривые'!$B$5:$L$5,1,MATCH(C12,'Исходные кривые'!$B$4:$L$4,1))+(C12-INDEX('Исходные кривые'!$B$4:$L$4,1,MATCH(C12,'Исходные кривые'!$B$4:$L$4,1)))*(INDEX('Исходные кривые'!$B$5:$L$5,1,MATCH(C12,'Исходные кривые'!$B$4:$L$4,1)+1)-INDEX('Исходные кривые'!$B$5:$L$5,1,MATCH(C12,'Исходные кривые'!$B$4:$L$4,1)))/(INDEX('Исходные кривые'!$B$4:$L$4,1,MATCH(C12,'Исходные кривые'!$B$4:$L$4,1)+1)-INDEX('Исходные кривые'!$B$4:$L$4,1,MATCH(C12,'Исходные кривые'!$B$4:$L$4,1))))) -> 13.674658 | E12: =IF(C12<=MIN('Исходные кривые'!$B$8:$N$8),INDEX('Исходные кривые'!$B$9:$N$9,1,1),IF(C12>=MAX('Исходные кривые'!$B$8:$N$8),INDEX('Исходные кривые'!$B$9:$N$9,1,COLUMNS('Исходные кривые'!$B$9:$N$9)),INDEX('Исходные кривые'!$B$9:$N$9,1,MATCH(C12,'Исходные кривые'!$B$8:$N$8,1))+(C12-INDEX('Исходные кривые'!$B$8:$N$8,1,MATCH(C12,'Исходные кривые'!$B$8:$N$8,1)))*(INDEX('Исходные кривые'!$B$9:$N$9,1,MATCH(C12,'Исходные кривые'!$B$8:$N$8,1)+1)-INDEX('Исходные кривые'!$B$9:$N$9,1,MATCH(C12,'Исходные кривые'!$B$8:$N$8,1)))/(INDEX('Исходные кривые'!$B$8:$N$8,1,MATCH(C12,'Исходные кривые'!$B$8:$N$8,1)+1)-INDEX('Исходные кривые'!$B$8:$N$8,1,MATCH(C12,'Исходные кривые'!$B$8:$N$8,1))))) -> 15.674658 | F12: =IF(C12<=MIN('Исходные кривые'!$B$12:$K$12),INDEX('Исходные кривые'!$B$13:$K$13,1,1),IF(C12>=MAX('Исходные кривые'!$B$12:$K$12),INDEX('Исходные кривые'!$B$13:$K$13,1,COLUMNS('Исходные кривые'!$B$13:$K$13)),INDEX('Исходные кривые'!$B$13:$K$13,1,MATCH(C12,'Исходные кривые'!$B$12:$K$12,1))+(C12-INDEX('Исходные кривые'!$B$12:$K$12,1,MATCH(C12,'Исходные кривые'!$B$12:$K$12,1)))*(INDEX('Исходные кривые'!$B$13:$K$13,1,MATCH(C12,'Исходные кривые'!$B$12:$K$12,1)+1)-INDEX('Исходные кривые'!$B$13:$K$13,1,MATCH(C12,'Исходные кривые'!$B$12:$K$12,1)))/(INDEX('Исходные кривые'!$B$12:$K$12,1,MATCH(C12,'Исходные кривые'!$B$12:$K$12,1)+1)-INDEX('Исходные кривые'!$B$12:$K$12,1,MATCH(C12,'Исходные кривые'!$B$12:$K$12,1))))) -> 56.273973 | G12: =IF(C12<=MIN('Исходные кривые'!$B$12:$K$12),INDEX('Исходные кривые'!$B$14:$K$14,1,1),IF(C12>=MAX('Исходные кривые'!$B$12:$K$12),INDEX('Исходные кривые'!$B$14:$K$14,1,COLUMNS('Исходные кривые'!$B$14:$K$14)),INDEX('Исходные кривые'!$B$14:$K$14,1,MATCH(C12,'Исходные кривые'!$B$12:$K$12,1))+(C12-INDEX('Исходные кривые'!$B$12:$K$12,1,MATCH(C12,'Исходные кривые'!$B$12:$K$12,1)))*(INDEX('Исходные кривые'!$B$14:$K$14,1,MATCH(C12,'Исходные кривые'!$B$12:$K$12,1)+1)-INDEX('Исходные кривые'!$B$14:$K$14,1,MATCH(C12,'Исходные кривые'!$B$12:$K$12,1)))/(INDEX('Исходные кривые'!$B$12:$K$12,1,MATCH(C12,'Исходные кривые'!$B$12:$K$12,1)+1)-INDEX('Исходные кривые'!$B$12:$K$12,1,MATCH(C12,'Исходные кривые'!$B$12:$K$12,1))))) -> -29.849315 | H12: =IF(C12<=MIN('Исходные кривые'!$B$17:$L$17),INDEX('Исходные кривые'!$B$18:$L$18,1,1),IF(C12>=MAX('Исходные кривые'!$B$17:$L$17),INDEX('Исходные кривые'!$B$18:$L$18,1,COLUMNS('Исходные кривые'!$B$18:$L$18)),INDEX('Исходные кривые'!$B$18:$L$18,1,MATCH(C12,'Исходные кривые'!$B$17:$L$17,1))+(C12-INDEX('Исходные кривые'!$B$17:$L$17,1,MATCH(C12,'Исходные кривые'!$B$17:$L$17,1)))*(INDEX('Исходные кривые'!$B$18:$L$18,1,MATCH(C12,'Исходные кривые'!$B$17:$L$17,1)+1)-INDEX('Исходные кривые'!$B$18:$L$18,1,MATCH(C12,'Исходные кривые'!$B$17:$L$17,1)))/(INDEX('Исходные кривые'!$B$17:$L$17,1,MATCH(C12,'Исходные кривые'!$B$17:$L$17,1)+1)-INDEX('Исходные кривые'!$B$17:$L$17,1,MATCH(C12,'Исходные кривые'!$B$17:$L$17,1))))) -> 6.7191781 | I12: =IF(C12<=MIN('Исходные кривые'!$B$17:$L$17),INDEX('Исходные кривые'!$B$19:$L$19,1,1),IF(C12>=MAX('Исходные кривые'!$B$17:$L$17),INDEX('Исходные кривые'!$B$19:$L$19,1,COLUMNS('Исходные кривые'!$B$19:$L$19)),INDEX('Исходные кривые'!$B$19:$L$19,1,MATCH(C12,'Исходные кривые'!$B$17:$L$17,1))+(C12-INDEX('Исходные кривые'!$B$17:$L$17,1,MATCH(C12,'Исходные кривые'!$B$17:$L$17,1)))*(INDEX('Исходные кривые'!$B$19:$L$19,1,MATCH(C12,'Исходные кривые'!$B$17:$L$17,1)+1)-INDEX('Исходные кривые'!$B$19:$L$19,1,MATCH(C12,'Исходные кривые'!$B$17:$L$17,1)))/(INDEX('Исходные кривые'!$B$17:$L$17,1,MATCH(C12,'Исходные кривые'!$B$17:$L$17,1)+1)-INDEX('Исходные кривые'!$B$17:$L$17,1,MATCH(C12,'Исходные кривые'!$B$17:$L$17,1))))) -> -4.8273973
A13: 46960 | B13: =A13-Настройки!$B$4 -> 757 | C13: =B13/Настройки!$B$5 -> 2.0739726 | D13: =IF(C13<=MIN('Исходные кривые'!$B$4:$L$4),INDEX('Исходные кривые'!$B$5:$L$5,1,1),IF(C13>=MAX('Исходные кривые'!$B$4:$L$4),INDEX('Исходные кривые'!$B$5:$L$5,1,COLUMNS('Исходные кривые'!$B$5:$L$5)),INDEX('Исходные кривые'!$B$5:$L$5,1,MATCH(C13,'Исходные кривые'!$B$4:$L$4,1))+(C13-INDEX('Исходные кривые'!$B$4:$L$4,1,MATCH(C13,'Исходные кривые'!$B$4:$L$4,1)))*(INDEX('Исходные кривые'!$B$5:$L$5,1,MATCH(C13,'Исходные кривые'!$B$4:$L$4,1)+1)-INDEX('Исходные кривые'!$B$5:$L$5,1,MATCH(C13,'Исходные кривые'!$B$4:$L$4,1)))/(INDEX('Исходные кривые'!$B$4:$L$4,1,MATCH(C13,'Исходные кривые'!$B$4:$L$4,1)+1)-INDEX('Исходные кривые'!$B$4:$L$4,1,MATCH(C13,'Исходные кривые'!$B$4:$L$4,1))))) -> 13.914384 | E13: =IF(C13<=MIN('Исходные кривые'!$B$8:$N$8),INDEX('Исходные кривые'!$B$9:$N$9,1,1),IF(C13>=MAX('Исходные кривые'!$B$8:$N$8),INDEX('Исходные кривые'!$B$9:$N$9,1,COLUMNS('Исходные кривые'!$B$9:$N$9)),INDEX('Исходные кривые'!$B$9:$N$9,1,MATCH(C13,'Исходные кривые'!$B$8:$N$8,1))+(C13-INDEX('Исходные кривые'!$B$8:$N$8,1,MATCH(C13,'Исходные кривые'!$B$8:$N$8,1)))*(INDEX('Исходные кривые'!$B$9:$N$9,1,MATCH(C13,'Исходные кривые'!$B$8:$N$8,1)+1)-INDEX('Исходные кривые'!$B$9:$N$9,1,MATCH(C13,'Исходные кривые'!$B$8:$N$8,1)))/(INDEX('Исходные кривые'!$B$8:$N$8,1,MATCH(C13,'Исходные кривые'!$B$8:$N$8,1)+1)-INDEX('Исходные кривые'!$B$8:$N$8,1,MATCH(C13,'Исходные кривые'!$B$8:$N$8,1))))) -> 15.914384 | F13: =IF(C13<=MIN('Исходные кривые'!$B$12:$K$12),INDEX('Исходные кривые'!$B$13:$K$13,1,1),IF(C13>=MAX('Исходные кривые'!$B$12:$K$12),INDEX('Исходные кривые'!$B$13:$K$13,1,COLUMNS('Исходные кривые'!$B$13:$K$13)),INDEX('Исходные кривые'!$B$13:$K$13,1,MATCH(C13,'Исходные кривые'!$B$12:$K$12,1))+(C13-INDEX('Исходные кривые'!$B$12:$K$12,1,MATCH(C13,'Исходные кривые'!$B$12:$K$12,1)))*(INDEX('Исходные кривые'!$B$13:$K$13,1,MATCH(C13,'Исходные кривые'!$B$12:$K$12,1)+1)-INDEX('Исходные кривые'!$B$13:$K$13,1,MATCH(C13,'Исходные кривые'!$B$12:$K$12,1)))/(INDEX('Исходные кривые'!$B$12:$K$12,1,MATCH(C13,'Исходные кривые'!$B$12:$K$12,1)+1)-INDEX('Исходные кривые'!$B$12:$K$12,1,MATCH(C13,'Исходные кривые'!$B$12:$K$12,1))))) -> 54.926027 | G13: =IF(C13<=MIN('Исходные кривые'!$B$12:$K$12),INDEX('Исходные кривые'!$B$14:$K$14,1,1),IF(C13>=MAX('Исходные кривые'!$B$12:$K$12),INDEX('Исходные кривые'!$B$14:$K$14,1,COLUMNS('Исходные кривые'!$B$14:$K$14)),INDEX('Исходные кривые'!$B$14:$K$14,1,MATCH(C13,'Исходные кривые'!$B$12:$K$12,1))+(C13-INDEX('Исходные кривые'!$B$12:$K$12,1,MATCH(C13,'Исходные кривые'!$B$12:$K$12,1)))*(INDEX('Исходные кривые'!$B$14:$K$14,1,MATCH(C13,'Исходные кривые'!$B$12:$K$12,1)+1)-INDEX('Исходные кривые'!$B$14:$K$14,1,MATCH(C13,'Исходные кривые'!$B$12:$K$12,1)))/(INDEX('Исходные кривые'!$B$12:$K$12,1,MATCH(C13,'Исходные кривые'!$B$12:$K$12,1)+1)-INDEX('Исходные кривые'!$B$12:$K$12,1,MATCH(C13,'Исходные кривые'!$B$12:$K$12,1))))) -> -28.926027 | H13: =IF(C13<=MIN('Исходные кривые'!$B$17:$L$17),INDEX('Исходные кривые'!$B$18:$L$18,1,1),IF(C13>=MAX('Исходные кривые'!$B$17:$L$17),INDEX('Исходные кривые'!$B$18:$L$18,1,COLUMNS('Исходные кривые'!$B$18:$L$18)),INDEX('Исходные кривые'!$B$18:$L$18,1,MATCH(C13,'Исходные кривые'!$B$17:$L$17,1))+(C13-INDEX('Исходные кривые'!$B$17:$L$17,1,MATCH(C13,'Исходные кривые'!$B$17:$L$17,1)))*(INDEX('Исходные кривые'!$B$18:$L$18,1,MATCH(C13,'Исходные кривые'!$B$17:$L$17,1)+1)-INDEX('Исходные кривые'!$B$18:$L$18,1,MATCH(C13,'Исходные кривые'!$B$17:$L$17,1)))/(INDEX('Исходные кривые'!$B$17:$L$17,1,MATCH(C13,'Исходные кривые'!$B$17:$L$17,1)+1)-INDEX('Исходные кривые'!$B$17:$L$17,1,MATCH(C13,'Исходные кривые'!$B$17:$L$17,1))))) -> 7.1871233 | I13: =IF(C13<=MIN('Исходные кривые'!$B$17:$L$17),INDEX('Исходные кривые'!$B$19:$L$19,1,1),IF(C13>=MAX('Исходные кривые'!$B$17:$L$17),INDEX('Исходные кривые'!$B$19:$L$19,1,COLUMNS('Исходные кривые'!$B$19:$L$19)),INDEX('Исходные кривые'!$B$19:$L$19,1,MATCH(C13,'Исходные кривые'!$B$17:$L$17,1))+(C13-INDEX('Исходные кривые'!$B$17:$L$17,1,MATCH(C13,'Исходные кривые'!$B$17:$L$17,1)))*(INDEX('Исходные кривые'!$B$19:$L$19,1,MATCH(C13,'Исходные кривые'!$B$17:$L$17,1)+1)-INDEX('Исходные кривые'!$B$19:$L$19,1,MATCH(C13,'Исходные кривые'!$B$17:$L$17,1)))/(INDEX('Исходные кривые'!$B$17:$L$17,1,MATCH(C13,'Исходные кривые'!$B$17:$L$17,1)+1)-INDEX('Исходные кривые'!$B$17:$L$17,1,MATCH(C13,'Исходные кривые'!$B$17:$L$17,1))))) -> -4.6223288
A14: 47142 | B14: =A14-Настройки!$B$4 -> 939 | C14: =B14/Настройки!$B$5 -> 2.5726027 | D14: =IF(C14<=MIN('Исходные кривые'!$B$4:$L$4),INDEX('Исходные кривые'!$B$5:$L$5,1,1),IF(C14>=MAX('Исходные кривые'!$B$4:$L$4),INDEX('Исходные кривые'!$B$5:$L$5,1,COLUMNS('Исходные кривые'!$B$5:$L$5)),INDEX('Исходные кривые'!$B$5:$L$5,1,MATCH(C14,'Исходные кривые'!$B$4:$L$4,1))+(C14-INDEX('Исходные кривые'!$B$4:$L$4,1,MATCH(C14,'Исходные кривые'!$B$4:$L$4,1)))*(INDEX('Исходные кривые'!$B$5:$L$5,1,MATCH(C14,'Исходные кривые'!$B$4:$L$4,1)+1)-INDEX('Исходные кривые'!$B$5:$L$5,1,MATCH(C14,'Исходные кривые'!$B$4:$L$4,1)))/(INDEX('Исходные кривые'!$B$4:$L$4,1,MATCH(C14,'Исходные кривые'!$B$4:$L$4,1)+1)-INDEX('Исходные кривые'!$B$4:$L$4,1,MATCH(C14,'Исходные кривые'!$B$4:$L$4,1))))) -> 14.213562 | E14: =IF(C14<=MIN('Исходные кривые'!$B$8:$N$8),INDEX('Исходные кривые'!$B$9:$N$9,1,1),IF(C14>=MAX('Исходные кривые'!$B$8:$N$8),INDEX('Исходные кривые'!$B$9:$N$9,1,COLUMNS('Исходные кривые'!$B$9:$N$9)),INDEX('Исходные кривые'!$B$9:$N$9,1,MATCH(C14,'Исходные кривые'!$B$8:$N$8,1))+(C14-INDEX('Исходные кривые'!$B$8:$N$8,1,MATCH(C14,'Исходные кривые'!$B$8:$N$8,1)))*(INDEX('Исходные кривые'!$B$9:$N$9,1,MATCH(C14,'Исходные кривые'!$B$8:$N$8,1)+1)-INDEX('Исходные кривые'!$B$9:$N$9,1,MATCH(C14,'Исходные кривые'!$B$8:$N$8,1)))/(INDEX('Исходные кривые'!$B$8:$N$8,1,MATCH(C14,'Исходные кривые'!$B$8:$N$8,1)+1)-INDEX('Исходные кривые'!$B$8:$N$8,1,MATCH(C14,'Исходные кривые'!$B$8:$N$8,1))))) -> 16.213562 | F14: =IF(C14<=MIN('Исходные кривые'!$B$12:$K$12),INDEX('Исходные кривые'!$B$13:$K$13,1,1),IF(C14>=MAX('Исходные кривые'!$B$12:$K$12),INDEX('Исходные кривые'!$B$13:$K$13,1,COLUMNS('Исходные кривые'!$B$13:$K$13)),INDEX('Исходные кривые'!$B$13:$K$13,1,MATCH(C14,'Исходные кривые'!$B$12:$K$12,1))+(C14-INDEX('Исходные кривые'!$B$12:$K$12,1,MATCH(C14,'Исходные кривые'!$B$12:$K$12,1)))*(INDEX('Исходные кривые'!$B$13:$K$13,1,MATCH(C14,'Исходные кривые'!$B$12:$K$12,1)+1)-INDEX('Исходные кривые'!$B$13:$K$13,1,MATCH(C14,'Исходные кривые'!$B$12:$K$12,1)))/(INDEX('Исходные кривые'!$B$12:$K$12,1,MATCH(C14,'Исходные кривые'!$B$12:$K$12,1)+1)-INDEX('Исходные кривые'!$B$12:$K$12,1,MATCH(C14,'Исходные кривые'!$B$12:$K$12,1))))) -> 54.427397 | G14: =IF(C14<=MIN('Исходные кривые'!$B$12:$K$12),INDEX('Исходные кривые'!$B$14:$K$14,1,1),IF(C14>=MAX('Исходные кривые'!$B$12:$K$12),INDEX('Исходные кривые'!$B$14:$K$14,1,COLUMNS('Исходные кривые'!$B$14:$K$14)),INDEX('Исходные кривые'!$B$14:$K$14,1,MATCH(C14,'Исходные кривые'!$B$12:$K$12,1))+(C14-INDEX('Исходные кривые'!$B$12:$K$12,1,MATCH(C14,'Исходные кривые'!$B$12:$K$12,1)))*(INDEX('Исходные кривые'!$B$14:$K$14,1,MATCH(C14,'Исходные кривые'!$B$12:$K$12,1)+1)-INDEX('Исходные кривые'!$B$14:$K$14,1,MATCH(C14,'Исходные кривые'!$B$12:$K$12,1)))/(INDEX('Исходные кривые'!$B$12:$K$12,1,MATCH(C14,'Исходные кривые'!$B$12:$K$12,1)+1)-INDEX('Исходные кривые'!$B$12:$K$12,1,MATCH(C14,'Исходные кривые'!$B$12:$K$12,1))))) -> -28.427397 | H14: =IF(C14<=MIN('Исходные кривые'!$B$17:$L$17),INDEX('Исходные кривые'!$B$18:$L$18,1,1),IF(C14>=MAX('Исходные кривые'!$B$17:$L$17),INDEX('Исходные кривые'!$B$18:$L$18,1,COLUMNS('Исходные кривые'!$B$18:$L$18)),INDEX('Исходные кривые'!$B$18:$L$18,1,MATCH(C14,'Исходные кривые'!$B$17:$L$17,1))+(C14-INDEX('Исходные кривые'!$B$17:$L$17,1,MATCH(C14,'Исходные кривые'!$B$17:$L$17,1)))*(INDEX('Исходные кривые'!$B$18:$L$18,1,MATCH(C14,'Исходные кривые'!$B$17:$L$17,1)+1)-INDEX('Исходные кривые'!$B$18:$L$18,1,MATCH(C14,'Исходные кривые'!$B$17:$L$17,1)))/(INDEX('Исходные кривые'!$B$17:$L$17,1,MATCH(C14,'Исходные кривые'!$B$17:$L$17,1)+1)-INDEX('Исходные кривые'!$B$17:$L$17,1,MATCH(C14,'Исходные кривые'!$B$17:$L$17,1))))) -> 6.7632877 | I14: =IF(C14<=MIN('Исходные кривые'!$B$17:$L$17),INDEX('Исходные кривые'!$B$19:$L$19,1,1),IF(C14>=MAX('Исходные кривые'!$B$17:$L$17),INDEX('Исходные кривые'!$B$19:$L$19,1,COLUMNS('Исходные кривые'!$B$19:$L$19)),INDEX('Исходные кривые'!$B$19:$L$19,1,MATCH(C14,'Исходные кривые'!$B$17:$L$17,1))+(C14-INDEX('Исходные кривые'!$B$17:$L$17,1,MATCH(C14,'Исходные кривые'!$B$17:$L$17,1)))*(INDEX('Исходные кривые'!$B$19:$L$19,1,MATCH(C14,'Исходные кривые'!$B$17:$L$17,1)+1)-INDEX('Исходные кривые'!$B$19:$L$19,1,MATCH(C14,'Исходные кривые'!$B$17:$L$17,1)))/(INDEX('Исходные кривые'!$B$17:$L$17,1,MATCH(C14,'Исходные кривые'!$B$17:$L$17,1)+1)-INDEX('Исходные кривые'!$B$17:$L$17,1,MATCH(C14,'Исходные кривые'!$B$17:$L$17,1))))) -> -4.0987671
A15: 47324 | B15: =A15-Настройки!$B$4 -> 1121 | C15: =B15/Настройки!$B$5 -> 3.0712329 | D15: =IF(C15<=MIN('Исходные кривые'!$B$4:$L$4),INDEX('Исходные кривые'!$B$5:$L$5,1,1),IF(C15>=MAX('Исходные кривые'!$B$4:$L$4),INDEX('Исходные кривые'!$B$5:$L$5,1,COLUMNS('Исходные кривые'!$B$5:$L$5)),INDEX('Исходные кривые'!$B$5:$L$5,1,MATCH(C15,'Исходные кривые'!$B$4:$L$4,1))+(C15-INDEX('Исходные кривые'!$B$4:$L$4,1,MATCH(C15,'Исходные кривые'!$B$4:$L$4,1)))*(INDEX('Исходные кривые'!$B$5:$L$5,1,MATCH(C15,'Исходные кривые'!$B$4:$L$4,1)+1)-INDEX('Исходные кривые'!$B$5:$L$5,1,MATCH(C15,'Исходные кривые'!$B$4:$L$4,1)))/(INDEX('Исходные кривые'!$B$4:$L$4,1,MATCH(C15,'Исходные кривые'!$B$4:$L$4,1)+1)-INDEX('Исходные кривые'!$B$4:$L$4,1,MATCH(C15,'Исходные кривые'!$B$4:$L$4,1))))) -> 14.503836 | E15: =IF(C15<=MIN('Исходные кривые'!$B$8:$N$8),INDEX('Исходные кривые'!$B$9:$N$9,1,1),IF(C15>=MAX('Исходные кривые'!$B$8:$N$8),INDEX('Исходные кривые'!$B$9:$N$9,1,COLUMNS('Исходные кривые'!$B$9:$N$9)),INDEX('Исходные кривые'!$B$9:$N$9,1,MATCH(C15,'Исходные кривые'!$B$8:$N$8,1))+(C15-INDEX('Исходные кривые'!$B$8:$N$8,1,MATCH(C15,'Исходные кривые'!$B$8:$N$8,1)))*(INDEX('Исходные кривые'!$B$9:$N$9,1,MATCH(C15,'Исходные кривые'!$B$8:$N$8,1)+1)-INDEX('Исходные кривые'!$B$9:$N$9,1,MATCH(C15,'Исходные кривые'!$B$8:$N$8,1)))/(INDEX('Исходные кривые'!$B$8:$N$8,1,MATCH(C15,'Исходные кривые'!$B$8:$N$8,1)+1)-INDEX('Исходные кривые'!$B$8:$N$8,1,MATCH(C15,'Исходные кривые'!$B$8:$N$8,1))))) -> 16.503836 | F15: =IF(C15<=MIN('Исходные кривые'!$B$12:$K$12),INDEX('Исходные кривые'!$B$13:$K$13,1,1),IF(C15>=MAX('Исходные кривые'!$B$12:$K$12),INDEX('Исходные кривые'!$B$13:$K$13,1,COLUMNS('Исходные кривые'!$B$13:$K$13)),INDEX('Исходные кривые'!$B$13:$K$13,1,MATCH(C15,'Исходные кривые'!$B$12:$K$12,1))+(C15-INDEX('Исходные кривые'!$B$12:$K$12,1,MATCH(C15,'Исходные кривые'!$B$12:$K$12,1)))*(INDEX('Исходные кривые'!$B$13:$K$13,1,MATCH(C15,'Исходные кривые'!$B$12:$K$12,1)+1)-INDEX('Исходные кривые'!$B$13:$K$13,1,MATCH(C15,'Исходные кривые'!$B$12:$K$12,1)))/(INDEX('Исходные кривые'!$B$12:$K$12,1,MATCH(C15,'Исходные кривые'!$B$12:$K$12,1)+1)-INDEX('Исходные кривые'!$B$12:$K$12,1,MATCH(C15,'Исходные кривые'!$B$12:$K$12,1))))) -> 53.786301 | G15: =IF(C15<=MIN('Исходные кривые'!$B$12:$K$12),INDEX('Исходные кривые'!$B$14:$K$14,1,1),IF(C15>=MAX('Исходные кривые'!$B$12:$K$12),INDEX('Исходные кривые'!$B$14:$K$14,1,COLUMNS('Исходные кривые'!$B$14:$K$14)),INDEX('Исходные кривые'!$B$14:$K$14,1,MATCH(C15,'Исходные кривые'!$B$12:$K$12,1))+(C15-INDEX('Исходные кривые'!$B$12:$K$12,1,MATCH(C15,'Исходные кривые'!$B$12:$K$12,1)))*(INDEX('Исходные кривые'!$B$14:$K$14,1,MATCH(C15,'Исходные кривые'!$B$12:$K$12,1)+1)-INDEX('Исходные кривые'!$B$14:$K$14,1,MATCH(C15,'Исходные кривые'!$B$12:$K$12,1)))/(INDEX('Исходные кривые'!$B$12:$K$12,1,MATCH(C15,'Исходные кривые'!$B$12:$K$12,1)+1)-INDEX('Исходные кривые'!$B$12:$K$12,1,MATCH(C15,'Исходные кривые'!$B$12:$K$12,1))))) -> -27.964384 | H15: =IF(C15<=MIN('Исходные кривые'!$B$17:$L$17),INDEX('Исходные кривые'!$B$18:$L$18,1,1),IF(C15>=MAX('Исходные кривые'!$B$17:$L$17),INDEX('Исходные кривые'!$B$18:$L$18,1,COLUMNS('Исходные кривые'!$B$18:$L$18)),INDEX('Исходные кривые'!$B$18:$L$18,1,MATCH(C15,'Исходные кривые'!$B$17:$L$17,1))+(C15-INDEX('Исходные кривые'!$B$17:$L$17,1,MATCH(C15,'Исходные кривые'!$B$17:$L$17,1)))*(INDEX('Исходные кривые'!$B$18:$L$18,1,MATCH(C15,'Исходные кривые'!$B$17:$L$17,1)+1)-INDEX('Исходные кривые'!$B$18:$L$18,1,MATCH(C15,'Исходные кривые'!$B$17:$L$17,1)))/(INDEX('Исходные кривые'!$B$17:$L$17,1,MATCH(C15,'Исходные кривые'!$B$17:$L$17,1)+1)-INDEX('Исходные кривые'!$B$17:$L$17,1,MATCH(C15,'Исходные кривые'!$B$17:$L$17,1))))) -> 6.3821918 | I15: =IF(C15<=MIN('Исходные кривые'!$B$17:$L$17),INDEX('Исходные кривые'!$B$19:$L$19,1,1),IF(C15>=MAX('Исходные кривые'!$B$17:$L$17),INDEX('Исходные кривые'!$B$19:$L$19,1,COLUMNS('Исходные кривые'!$B$19:$L$19)),INDEX('Исходные кривые'!$B$19:$L$19,1,MATCH(C15,'Исходные кривые'!$B$17:$L$17,1))+(C15-INDEX('Исходные кривые'!$B$17:$L$17,1,MATCH(C15,'Исходные кривые'!$B$17:$L$17,1)))*(INDEX('Исходные кривые'!$B$19:$L$19,1,MATCH(C15,'Исходные кривые'!$B$17:$L$17,1)+1)-INDEX('Исходные кривые'!$B$19:$L$19,1,MATCH(C15,'Исходные кривые'!$B$17:$L$17,1)))/(INDEX('Исходные кривые'!$B$17:$L$17,1,MATCH(C15,'Исходные кривые'!$B$17:$L$17,1)+1)-INDEX('Исходные кривые'!$B$17:$L$17,1,MATCH(C15,'Исходные кривые'!$B$17:$L$17,1))))) -> -3.5930137
